<?xml version="1.0"?>
<robot xmlns:xacro="http://ros.org/wiki/xacro" name="lite6">

  <!-- ===== Args ===== -->
  <xacro:arg name="robot_ip"      default="192.168.1.186"/>
  <xacro:arg name="report_type"   default="dev"/>
  <xacro:arg name="with_gripper"  default="false"/>
  <xacro:arg name="with_vacuum"   default="false"/>
  <xacro:arg name="prefix"        default=""/>
  <xacro:arg name="mesh_path"     default="package://xarm_description/meshes"/>
  <xacro:arg name="KIN_YAML"      default="$(find xarm_description)/config/kinematics/default/lite6_default_kinematics.yaml"/>
  <!-- INERTIAL_YAML ist der Config-Key-Name (ohne .yaml-Dateiendung) -->
  <xacro:arg name="INERTIAL_YAML" default="lite6_default_inertial"/>

  <!-- ===== Materials (optional, nur Optik) ===== -->
  <material name="White"><color rgba="0.9 0.9 0.9 1.0"/></material>
  <material name="Silver"><color rgba="0.75 0.75 0.75 1.0"/></material>

  <!-- ===== Includes: Arm + Common ===== -->
  <xacro:include filename="$(find xarm_description)/urdf/common/common.link.xacro"/>
  <xacro:include filename="$(find xarm_description)/urdf/common/common.material.xacro"/>
  <xacro:include filename="$(find xarm_description)/urdf/xarm_device_macro.xacro"/>
  <xacro:include filename="$(find xarm_description)/urdf/lite6/lite6_robot_macro.xacro"/>

  <!-- ===== Includes: Gripper Makros ===== -->
  <xacro:include filename="$(find lite6xlerobi)/urdf/gripper/authentic_lite6_gripper.urdf.xacro"/>

  <!-- ===== Properties, die die Upstream-Makros erwarten ===== -->
  <xacro:property name="is_ros2" value="true"/>
  <xacro:property name="use_xacro_load_yaml" value="true"/>
  <xacro:property name="mesh_path"   value="$(arg mesh_path)"/>
  <xacro:property name="mesh_suffix" value="stl"/>
  <xacro:property name="prefix" value="$(arg prefix)"/>

  <!-- ===== Arm mit echter Hardware (echtes xArm Hardware Interface) ===== -->
  <xacro:lite6_robot
      prefix="${prefix}"
      model_num="0"
      velocity_control="false"
      hard_interface="ros2_control"
      ros2_control_plugin="uf_robot_hardware/UFRobotSystemHardware"
      robot_ip="$(arg robot_ip)"
      report_type="$(arg report_type)"
      add_gripper="$(arg with_gripper)"
      kinematics_params_filename="$(arg KIN_YAML)"
      inertial_params_filename="$(arg INERTIAL_YAML)"/>

  <!-- Stabiler Tool-Link als Andockpunkt (Endeffektor-Referenz) -->
  <link name="link_eef"/>
  <joint name="joint_eef" type="fixed">
    <parent link="link6"/>
    <child  link="link_eef"/>
    <origin xyz="0 0 0" rpy="0 0 0"/>
  </joint>

  <!-- ===== Parallel-Jaw Gripper (optional, komplett eigener modularer Lite6-Gripper) ===== -->
  <xacro:if value="$(arg with_gripper)">
    <!-- Unser komplett eigener authentischer Lite6-Gripper mit originalen Meshes und beweglichen Fingern -->
    <xacro:authentic_lite6_gripper_urdf
      prefix="${prefix}"
      attach_to="link_eef"
      attach_xyz="0 0 0"
      attach_rpy="0 0 0"/>
  </xacro:if>

  <!-- ===== Vacuum Gripper (optional) =====
       Einfache Vacuum Gripper Implementation f端r echte Hardware
       um Root-Link Konflikte zu vermeiden.
  -->
  <xacro:if value="$(arg with_vacuum)">
    <!-- Vacuum Gripper Link direkt an link_eef -->
    <link name="vacuum_gripper_link">
      <visual>
        <origin xyz="0 0 0.02" rpy="0 0 0"/>
        <geometry>
          <cylinder radius="0.02" length="0.04"/>
        </geometry>
        <material name="Silver"/>
      </visual>
      <collision>
        <origin xyz="0 0 0.02" rpy="0 0 0"/>
        <geometry>
          <cylinder radius="0.02" length="0.04"/>
        </geometry>
      </collision>
      <inertial>
        <mass value="0.1"/>
        <origin xyz="0 0 0.02" rpy="0 0 0"/>
        <inertia ixx="0.0001" ixy="0" ixz="0" iyy="0.0001" iyz="0" izz="0.0001"/>
      </inertial>
    </link>
    
    <!-- Fixed Joint zum Roboter -->
    <joint name="vacuum_gripper_joint" type="fixed">
      <parent link="link_eef"/>
      <child  link="vacuum_gripper_link"/>
      <origin xyz="0 0 0" rpy="0 0 0"/>
    </joint>

    <!-- Vacuum Gripper Tip Link f端r das Joint -->
    <link name="vacuum_tip_link">
      <inertial>
        <mass value="0.01"/>
        <origin xyz="0 0 0" rpy="0 0 0"/>
        <inertia ixx="0.00001" ixy="0" ixz="0" iyy="0.00001" iyz="0" izz="0.00001"/>
      </inertial>
    </link>

    <!-- Virtueller Vacuum Aktor f端r ros2_control -->
    <joint name="vacuum_joint" type="prismatic">
      <parent link="vacuum_gripper_link"/>
      <child  link="vacuum_tip_link"/>
      <origin xyz="0 0 0.02" rpy="0 0 0"/>
      <axis xyz="0 0 1"/>
      <limit lower="0" upper="1" effort="10" velocity="1"/>
    </joint>

    <!-- ros2_control f端r Vacuum Gripper (echte Hardware) -->
    <ros2_control name="vacuum_gripper_controller" type="system">
      <hardware>
        <plugin>uf_robot_hardware/UFRobotVacuumHardware</plugin>
        <param name="robot_ip">$(arg robot_ip)</param>
        <param name="report_type">$(arg report_type)</param>
      </hardware>
      <joint name="vacuum_joint">
        <command_interface name="position"/>
        <state_interface name="position"/>
        <state_interface name="velocity"/>
      </joint>
    </ros2_control>
  </xacro:if>

</robot>